Workbook

Sheet Total Cash Flow
B1: Sale Value | C1: =17.67 -> 17.67
B2: Capex | C2: 15.77
B3: Opex | C3: 1.9
B5: Cost Price | F5: Customer payment terms
B6: IT | C6: 5.54
B7: NON-IT | C7: 2.34 | F7: Capex Payment Terms | G7: 30% Advance, 40% Delivery, 25% Against Completion, 5% after DLP period 1 years
B8: Implementation & PMC | C8: 1.44 | F8: Opex Payment Terms | G8: 6 months advance, 6 months in arrears
B9: Opex Cost | C9: 1.44
B10: Capex BG Cost for 2 years - 3% | C10: =C2*3%*4%*2 -> 0.037848 | F10: OEM Payment terms
B11: ABG Cost (30% for 6 months) | C11: =C2*30%*4%/2 -> 0.09462
B12: O&M PG Cost - 10% of year with 3 years, 3 months | C12: =C3/3*10%*4%*3.25 -> 0.0082333333 | F12: IT | G12: 120 Days
B13: Risk Cost - NON-IT/Insurance/PM Tools | C13: 0.5 | F13: Non-IT | G13: Against delivery
B14: Misc cost | C14: 0.5
B15: Frieght | C15: 0.68
B16: Total Cost | C16: =SUM(C6:C15) -> 12.580701
B17: Interest | C17: =I72 -> 0
B18: Total Cost with Interest | C18: =C16+C17 -> 12.580701
B19: Margin | C19: =1-C18/C1 -> 0.28801917
B20: Net Margin amount | C20: =C1-C18 -> 5.0892987
H21: Interest | I21: 0.01
B22: Financial Year | C22: Month | D22: Cash Inflow | F22: Cash outflow | H22: Net Cash Flow
E23: Total Inflow
B24: FY | C24: Month | E24: Total Inflow | G24: Total Outflow | H24: Nett Cash | I24: Interest | J24: Net Cash Flow
B25: 2026 | C25: Feb-26 | D25: =C2*30% -> 4.731 | E25: =D25 -> 4.731 | F25: =C10+C11+(C8/9) -> 0.292468 | G25: =F25 -> 0.292468 | H25: =E25-G25 -> 4.438532 | I25: =IF(H25<0,H25*1%,0) -> 0 | J25: =H25+I25 -> 4.438532
B26: 2026 | C26: Mar-26 | E26: =D26 -> 0 | F26: =C7+(C8/9) -> 2.5 | G26: =F26 -> 2.5 | H26: =E26-G26+J25 -> 1.938532 | I26: =IF(H26<0,H26*1%,0) -> 0 | J26: =H26+I26 -> 1.938532
B27: 2027 | C27: Apr-26 | D27: =C2*40% -> 6.308 | E27: =D27 -> 6.308 | F27: =C8/9+C14+C13+C15 -> 1.84 | G27: =F27 -> 1.84 | H27: =E27-G27+J26 -> 6.406532 | I27: =IF(H27<0,H27*1%,0) -> 0 | J27: =H27+I27 -> 6.406532
B28: 2027 | C28: May-26 | E28: =D28 -> 0 | F28: =C8/9 -> 0.16 | G28: =F28 -> 0.16 | H28: =E28-G28+J27 -> 6.246532 | I28: =IF(H28<0,H28*1%,0) -> 0 | J28: =H28+I28 -> 6.246532
B29: 2027 | C29: Jun-26 | E29: =D29 -> 0 | F29: =C6+(C8/9) -> 5.7 | G29: =F29 -> 5.7 | H29: =E29-G29+J28 -> 0.546532 | I29: =IF(H29<0,H29*1%,0) -> 0 | J29: =H29+I29 -> 0.546532
B30: 2027 | C30: 46204 | E30: =D30 -> 0 | F30: =C9/9 -> 0.16 | G30: =F30 -> 0.16 | H30: =E30-G30+J29 -> 0.386532 | I30: =IF(H30<0,H30*1%,0) -> 0 | J30: =H30+I30 -> 0.386532
B31: 2027 | C31: 46235 | E31: =D31 -> 0 | F31: =C8/9 -> 0.16 | G31: =F31 -> 0.16 | H31: =E31-G31+J30 -> 0.226532 | I31: =IF(H31<0,H31*1%,0) -> 0 | J31: =H31+I31 -> 0.226532
B32: 2027 | C32: 46266 | E32: =D32 -> 0 | F32: =C8/9 -> 0.16 | G32: =F32 -> 0.16 | H32: =E32-G32+J31 -> 0.066532 | I32: =IF(H32<0,H32*1%,0) -> 0 | J32: =H32+I32 -> 0.066532
B33: 2027 | C33: 46296 | D33: =C2*25% -> 3.9425 | E33: =D33 -> 3.9425 | F33: =C8/9 -> 0.16 | G33: =F33 -> 0.16 | H33: =E33-G33+J32 -> 3.849032 | I33: =IF(H33<0,H33*1%,0) -> 0 | J33: =H33+I33 -> 3.849032
B34: 2027 | C34: 46327 | D34: =C3/100%/6 -> 0.31666667 | E34: =D34 -> 0.31666667 | F34: =C12+C9/36 -> 0.048233333 | G34: =F34 -> 0.048233333 | H34: =E34-G34+J33 -> 4.1174653 | I34: =IF(H34<0,H34*1%,0) -> 0 | J34: =H34+I34 -> 4.1174653
B35: 2027 | C35: 46357 | E35: =D35 -> 0 | F35: =$C$9/36 -> 0.04 | G35: =F35 -> 0.04 | H35: =E35-G35+J34 -> 4.0774653 | I35: =IF(H35<0,H35*1%,0) -> 0 | J35: =H35+I35 -> 4.0774653
B36: 2027 | C36: 46388 | E36: =D36 -> 0 | F36: =$C$9/36 -> 0.04 | G36: =F36 -> 0.04 | H36: =E36-G36+J35 -> 4.0374653 | I36: =IF(H36<0,H36*1%,0) -> 0 | J36: =H36+I36 -> 4.0374653
B37: 2027 | C37: 46419 | E37: =D37 -> 0 | F37: =$C$9/36 -> 0.04 | G37: =F37 -> 0.04 | H37: =E37-G37+J36 -> 3.9974653 | I37: =IF(H37<0,H37*1%,0) -> 0 | J37: =H37+I37 -> 3.9974653
B38: 2027 | C38: 46447 | E38: =D38 -> 0 | F38: =$C$9/36 -> 0.04 | G38: =F38 -> 0.04 | H38: =E38-G38+J37 -> 3.9574653 | I38: =IF(H38<0,H38*1%,0) -> 0 | J38: =H38+I38 -> 3.9574653
B39: 2028 | C39: 46478 | E39: =D39 -> 0 | F39: =$C$9/36 -> 0.04 | G39: =F39 -> 0.04 | H39: =E39-G39+J38 -> 3.9174653 | I39: =IF(H39<0,H39*1%,0) -> 0 | J39: =H39+I39 -> 3.9174653
B40: 2028 | C40: 46508 | E40: =D40 -> 0 | F40: =$C$9/36 -> 0.04 | G40: =F40 -> 0.04 | H40: =E40-G40+J39 -> 3.8774653 | I40: =IF(H40<0,H40*1%,0) -> 0 | J40: =H40+I40 -> 3.8774653
B41: 2028 | C41: 46539 | E41: =D41 -> 0 | F41: =$C$9/36 -> 0.04 | G41: =F41 -> 0.04 | H41: =E41-G41+J40 -> 3.8374653 | I41: =IF(H41<0,H41*1%,0) -> 0 | J41: =H41+I41 -> 3.8374653
...

Sheet Summary
B3: Solution : In-row Cooling solution with 08 IT racks
B4: S.No. | C4: Description | D4: Total Price | F4: Discovered Prices | G4: Risks | H4: Total
B5: A | C5: Supply, installation, testing and commissioning of Data Center IT infrastructure | D5: ='IT Components'!G27 -> 101826890 | F5: ='IT Components'!K27 -> 69839137 | G5: 0 | H5: =F5+G5 -> 69839137
B6: B | C6: Supply, installation, testing and commissioning of Data Center non-IT infrastructure | D6: =' Non-IT components'!F26 -> 49066536 | F6: =' Non-IT components'!J28 -> 23398815 | G6: 5000000 | H6: =F6+G6 -> 28398815
B7: C | C7: Freight & Insurance (for A and B) | D7: 6800000 | F7: =D7 -> 6800000 | G7: 0 | H7: =F7+G7 -> 6800000
B8: D | C8: Hybrid Operation & Maintenance support for 3 years | D8: ='Support 3 Years'!G5 -> 19058470 | F8: ='Support 3 Years'!K6 -> 14400000 | G8: 0 | H8: =F8+G8 -> 14400000
B9: F | C9: Total of A to D | D9: =SUM(D5:D8) -> 1.767519e+08 | F9: =SUM(F5:F8) -> 114437952 | H9: =SUM(H5:H8) -> 119437952
B10: H | C10: Grand Total | D10: =D9 -> 1.767519e+08 | G10: Misc Cost | H10: 5000000
B11: Terms & Conditions
B12: Prices | C12: 1.Prices are exclusive of all applicable taxes in India. The same will be charged seperately as per actuals. | G12: Total | H12: =SUM(H9+H10) -> 124437952
C13: 2. The Prices are FOB Indian Port. Freight costs are mentioned separately for transportation by SEA. However, MEA need to provide all necessary documentation to facilitate export of these items. The local taxes and duties will be paid by MEA directly. | G13: Margin | H13: =1-H12/D9 -> 0.29597388
C14: 3. All invoices will be done to MEA, India inclusive of GST. | G14: Net Margin Amount | H14: =D10-H12 -> 52313944
C15: 4. MEA shall provide all customs exemption document whatever applicable / requested by Freight forwarder and local customs authorities as per International rules and regulations.
C16: 5. Any local duties and taxes applicable at the transit / destination port will be paid on actuals by MEA. Should there be any details sought by the Ethiopian customs, MEA shall facilitate the discussion by sending local personnel as required to meet the authority.
C17: 6. MEA shall facilitate all visa and work permit for RailTel and its designated contractors through the project.
B18: Project Execution | C18: 1. MoFA Ethiopia will share their project plan for those activities which are entrusted to them like Civil, Electrical, Comfort cooling etc. Based on their projcect plan RailTel will plan its resources, deliveries of various items and installation. Accordingly, the deliveries will be done within 30 days from the date of site rediness by MoFA//Ethiopia as per RailTel's satisfaction. 2. Project shall be completed within 4 months from the date of receipt of goods at the destination or site rediness in terms of civil and Elctrical Infrastracture by MoFA Ethiopia whichever is later. 3. Any delay arising due to freight movements in international water or geo-political disturbances or site non-availability or local workmanship disturbances or situations beyond our ability to influence shall call for delay in execution of the project. 4. Railtel shall not be held accountable for delays attributed beyond its capacity.
B19: Support | C19: Comprehensive support for 3 years shall be given for all quoted items under RailTel's scope of supply. Make In India products do not carry international warranty as the distribution zones are still not established in international waters. For parts failures, Railtel undertakes to replace the items at its cost. However, MEA shall facilitate in the transportation of spares and customs exemption in such scenario.

Sheet IT Components
A1: IT Services for Data Center
A2: SN | B2: Item Description | C2: Specifications | D2: Unit | E2: Qty | F2: Rate per unit (INR) | G2: Total Amount INR | H2: Probable OEM | J2: Unit Cost Ptice | K2: Total Cost Price
A3: 1 | B3: Server | C3: 2 x 16 Core Processor, 512 GB RAM, 20TB SSD (60TB SSD Usable capacity across the all 6 nodes) | D3: No | E3: 6 | F3: =3959570-750000 -> 3209570 | G3: =F3*E3 -> 19257420 | H3: HPE/Nutanix | J3: 27000000 | K3: 27000000
A4: 14 | B4: Virtualization (Cloud Application) | C4: Hypervisor for Six Servers (Quantity will depend on OEM solution) | D4: Lumsum | E4: 1 | F4: 13200000 | G4: =F4*E4 -> 13200000 | H4: Nutanix
A5: 2 | B5: Storage / Disaster Recovery Devices | C5: NAS High Convergence Storage Total 240 TB NLSAS HDD Usable Storage (Used for Backup purpose) | D5: No | E5: 2 | F5: 4710150 | G5: =F5*E5 -> 9420300 | H5: NetAPP | J5: 3250000 | K5: =J5*E5 -> 6500000
A6: 3 | B6: Firewall (For Internet) with VPN Module | C6: IPSec VPN throughput - 1 Gbps, Firewall throughput 10 Gbps, Threat prevention throughput - 1 Gbps with 36 Months Support & License, SSL VPN 10 Clients | D6: No | E6: 2 | F6: 556310 | G6: =F6*E6 -> 1112620 | H6: Fortinet | J6: 450000 | K6: =J6*E6 -> 900000
A7: 4 | B7: Firewall (For Intranet) with VPN Module | C7: IPSec VPN throughput - 1 Gbps, Firewall throughput 10 Gbps, Threat prevention throughput - 1 Gbps with 36 Months Support & License, SSL VPN 200 Clients | D7: No | E7: 2 | F7: 935310 | G7: =F7*E7 -> 1870620 | H7: Fortinet | J7: 500000 | K7: =J7*E7 -> 1000000
A8: 5 | B8: Server Security with 3 Years Support | C8: Protection Against Viruses and trojans Spyware and rootkits | D8: No | E8: 50 | F8: 40000 | G8: =F8*E8 -> 2000000 | H8: Seqrite | J8: 10000 | K8: =J8*E8 -> 500000
A9: 6 | B9: Backup Software with 3 Years Support | C9: Backup Solution for DC | D9: No | E9: 1 | F9: 1884060 | G9: =F9*E9 -> 1884060 | H9: Veeam - 50 VMs | J9: 1500000 | K9: =J9*E9 -> 1500000
A10: 7 | B10: Router | C10: Router throughput of 80Gbps, 8x10G ports and 4 x1G LAN ports with 36 Months Service & Support. Loaded with 6 10G LR and 2 10G SR interfaces | D10: No | E10: 2 | F10: 1950000 | G10: =F10*E10 -> 3900000 | H10: Arista | J10: 7500000 | K10: =J10*1 -> 7500000
A11: 8 | B11: Core Switch | C11: 48-port x 1/10/25G + 4-port 40/100G, with 36 Months Service & Support, minimum throughput 3.2 Tbps with 16 SR and 8 LR Transceivers | D11: No | E11: 2 | F11: 2448900 | G11: =F11*E11 -> 4897800 | H11: Arista
A12: 9 | B12: WAN Switch | C12: 24px1G/ 4x10G Uplink with 36 Months Service & Support with 2 LR optics | D12: No | E12: 2 | F12: 285000 | G12: =F12*E12 -> 570000 | H12: Arista
A13: 10 | B13: Top Of Rack SW (TOR) | C13: 24 x10G SFP+ ports with 36 Months Service & Support with SR Transceivers | D13: No | E13: 2 | F13: 2248900 | G13: =F13*E13 -> 4497800 | H13: Arista
A14: 11 | B14: L2-Switch | C14: 24x1G PoE+, 4 x 10G with 36 Months Service & Support | D14: No | E14: 3 | F14: 125000 | G14: =F14*E14 -> 375000 | H14: Arista
A15: 24 | B15: L2-Switch | C15: 24x1G PoE+, 4 x 10G with 36 Months Service & Support | D15: No | E15: 5 | F15: 125000 | G15: =F15*E15 -> 625000 | H15: Arista
A16: 12 | B16: Network Accessories | C16: 1. Network cabling for 8 racks includes Fiber OM4, Cat 6A Cable, Fibre Parch Cords, Patch Panels etc. 2. 2xTelco racks and PDUs | D16: Lumsum | E16: 1 | F16: =4599790-900000 -> 3699790 | G16: =F16*E16 -> 3699790 | H16: 3C3/R&M | J16: 2100000 | K16: =J16*1 -> 2100000
A17: 13 | B17: Server Accessories | C17: 8 Server Room IT racks | D17: Lumsum | E17: 1 | F17: =3077640-160000-500000-700000 -> 1717640 | G17: =F17*E17 -> 1717640 | H17: Netrack/Vertiv | J17: 900000 | K17: =J17*1 -> 900000
A18: 15 | B18: SQL Licenses | C18: MS Sql server Standard latest version (licence per 8 Core) | D18: No | E18: 2 | F18: 1750000 | G18: =F18*E18 -> 3500000 | H18: Microsoft | J18: =290743*4 -> 1162972 | K18: =J18*E18 -> 2325944
A19: 16 | B19: OS Licenses (Linux) | C19: Redhat Data Center Licenses with 3 year standard support | D19: No. | E19: 3 | F19: 665000 | G19: =F19*E19 -> 1995000 | H19: Redhat | J19: =179915*3 -> 539745 | K19: =J19*E19 -> 1619235
A20: 17 | B20: OS Licenses(Windows) | C20: MS Windows Server Datacenter latest version (License per 32 core) | D20: No. | E20: 3 | F20: 1159430 | G20: =F20*E20 -> 3478290 | H20: Microsoft | J20: =498993*2 -> 997986 | K20: =J20*E20 -> 2993958
A21: 18 | B21: Monitoring Solution | C21: License per Virtual Machines | D21: No. | E21: 1 | F21: 1000000 | G21: =F21*E21 -> 1000000 | H21: Open NMS/Zabbix | J21: 0
A22: 19 | B22: Design, Installation, Testing Commissioning | C22: Design, Installation, testing, commissioning and documentation of each subsystem | D22: Lumsum | E22: 1 | F22: =24000000-1500000-1000000 -> 21500000 | G22: =F22*E22 -> 21500000 | J22: ='Implementation Resources'!H15 -> 14400000 | K22: =J22*E22 -> 14400000
A23: 20 | B23: O&M Support for 3 Years | C23: Comprehensive Support for all supplied items as above. | D23: Lumsum | E23: 1 | F23: 0 | G23: =F23*E23 -> 0
A24: 21 | B24: Migration of Existing Services | C24: RailTel will provide only support during the migration activity . However the Migration activity will be done by MoFA team and any compatibility issue will be the responsibilty of MoFA. Support related to migrations is mentioned in the Migration support sheet | D24: Lumsum | E24: 1 | F24: 0 | G24: =F24*E24 -> 0
A25: 22 | B25: Workstation PC | C25: Workstation PC with I7 processor, 16GB RAM and 1TB SSD, with 21 inch display | D25: Nos | E25: 3 | F25: =325470 -> 325470 | G25: =F25*E25 -> 976410 | H25: HPI | J25: 125000 | K25: =J25*E25 -> 375000
A26: 23 | B26: LED display | C26: 55" LED display panels with HDMI connectivity & mounting brackets | D26: Nos | E26: 3 | F26: 116380 | G26: =F26*E26 -> 349140 | H26: Samsung/LG/Sony/Panasonic | J26: 75000 | K26: =J26*E26 -> 225000
C27: TOTAL | G27: =SUM(G3:G26) -> 101826890 | K27: =SUM(K3:K26) -> 69839137

Sheet  Non-IT components
A1: Non-IT Services for Data Center
A2: S. No. | B2: Item Descriotion | C2: UOM | D2: Qty | E2: Unit Rate | F2: Total Cost | G2: Recommended Brands
I4: Unit Price | J4: Total Price
A5: 1 | B5: Civil and Interior works comprising of demolition works, construction of partition walls, Supply and installation of Fire rated doors, installation of vinyl flooring, DG foundation and miscellaneous works. | C5: Lot | D5: 1 | E5: 9304500 | F5: =D5*E5 -> 9304500 | I5: 4000000 | J5: =I5*D5 -> 4000000
A6: 2 | B6: Supply and installation of furniture (worktable and chairs) for NOC room | C6: Nos. | D6: 3 | E6: 88958 | F6: =E6*D6 -> 266874 | I6: 44000 | J6: =I6*D6 -> 132000
A7: 5 | B7: Supply, installation, testing and commissioning of 60kVA UPS : | C7: Nos. | D7: 2 | E7: 4490000 | F7: =E7*D7 -> 8980000 | G7: This item is to be procured by MoFA/Ethiopia. Preferred Brands: Vertiv/Legrand or similar reputed make. | I7: 2250000 | J7: =I7*D7 -> 4500000
A8: 6 | B8: Supply, installation, testing and commissioning of Electrical Panels : | C8: Lot | D8: 1 | E8: 3450238 | F8: =E8*D8 -> 3450238 | G8: Make in India with reputed Switchgear elements | I8: 2132400 | J8: =I8*D8 -> 2132400
A9: 7 | B9: Supply, installation and testing of Lighting system | C9: Lot | D9: 1 | E9: =777280.5-5000 -> 772280.5 | F9: =E9*D9 -> 772280.5 | G9: Philips/Syska/Wipro etc. | I9: 319410 | J9: =I9*D9 -> 319410
A10: 8 | B10: Supply, installation, testing of Earthing system | C10: Lot | D10: 1 | E10: 1001822.5 | F10: =E10*D10 -> 1001822.5 | G10: Reputed Indian make | I10: 568200 | J10: =I10*D10 -> 568200
A11: 9 | B11: Supply of electrical safety aids | C11: Lot | D11: 1 | E11: 526832 | F11: =E11*D11 -> 526832 | G11: Reputed Indian make | I11: 262000 | J11: =I11*D11 -> 262000
A12: 10 | B12: Supply and installation of Cabling system for Data Centre including electrical switches and power sockets. | C12: Lot | D12: 1 | E12: 4256009 | F12: =E12*D12 -> 4256009 | G12: Reputed Indian make | I12: 1500000 | J12: =I12*D12 -> 1500000
A13: 11 | B13: Supply and installation of Mobile industrial sockets for IT racks. | C13: Nos. | D13: 20 | E13: 15903 | F13: =E13*D13 -> 318060 | G13: Reputed Indian make | I13: 8000 | J13: =I13*D13 -> 160000
A14: 12 | B14: Supply, installation, testing and commissioning of Inrow Cooling Units for the Server Room- 25kW | C14: Nos. | D14: 3 | E14: 2900000 | F14: =E14*D14 -> 8700000 | G14: Make in India Vertiv/Clima veneta or similar reputed make. | I14: 1500000 | J14: =I14*D14 -> 4500000
A15: 13 | B15: Supply, installation, testing and commissioning of comfort air conditioning system for Battery Room, Telco Room, Electrical Room and NOC | C15: Lot | D15: 1 | E15: =2280010-380000 -> 1900010 | F15: =E15*D15 -> 1900010 | G15: This item is to be procured by MoFA/Ethiopia | I15: 760000 | J15: =I15*D15 -> 760000
A16: 14 | B16: Supply, Installation, testing and commissioning of sequencers for ACs in Battery Room, Telco Room, Electrical Room | C16: Nos. | D16: 1 | E16: 345515 | F16: =E16*D16 -> 345515 | G16: This item is to be procured by MoFA/Ethiopia | I16: 81750 | J16: =I16*D16 -> 81750
A17: 15 | B17: Supply, installation, testing and commissioning of Fire Alarm System & VESDA | C17: Lot | D17: 1 | E17: =925832+300000 -> 1225832 | F17: =E17*D17 -> 1225832 | I17: 631000 | J17: =I17*D17 -> 631000
A18: 16 | B18: Supply, installation, testing and commissioning of clean agent based hand held fire extinguishers for Data Centre | C18: Lot | D18: 1 | E18: =410238.5-20000 -> 390238.5 | F18: =E18*D18 -> 390238.5 | I18: 195000 | J18: =I18*D18 -> 195000
A19: 17 | B19: Supply, installation, testing and commissioning of Gas based fire suppression system (NOVEC1230 or Equivalent for Server Room) | C19: Lot | D19: 1 | E19: =2860369*0.75 -> 2145276.8 | F19: =E19*D19 -> 2145276.8 | I19: 965000 | J19: =I19*D19 -> 965000
A20: 18 | B20: Supply, installation, testing and commissioning of Surveillance System | C20: Lot | D20: 1 | E20: =837738.5 -7000 -> 830738.5 | F20: =E20*D20 -> 830738.5 | G20: Reputed Indian make | I20: 350150 | J20: =I20*D20 -> 350150
A21: 19 | B21: Supply, installation, testing and commissioning of Access control system | C21: Lot | D21: 1 | E21: =1036374-20000 -> 1016374 | F21: =E21*D21 -> 1016374 | G21: Reputed Indian make | I21: 511820 | J21: =I21*D21 -> 511820
A22: 20 | B22: Supply, installation, testing and commissioning of Rodent Repellant System | C22: Lot | D22: 1 | E22: 190009.5 | F22: =E22*D22 -> 190009.5 | G22: Reputed Indian make | I22: 91250 | J22: =I22*D22 -> 91250
A23: 21 | B23: Supply, installation, testing and commissioning of Water leak detection system | C23: Lot | D23: 1 | E23: 155467.5 | F23: =E23*D23 -> 155467.5 | G23: Reputed Indian make | I23: 77715 | J23: =I23*D23 -> 77715
A24: 22 | B24: Supply, installation, testing and commissioning of BMS | C24: Lot | D24: 1 | E24: =2000000-5000 -> 1995000 | F24: =E24*D24 -> 1995000 | I24: 1014120 | J24: =I24*D24 -> 1014120
A25: 23 | B25: Supply & Installation of Containment for the 8 racks with doors : | C25: Set | D25: 1 | E25: 1295458 | F25: =E25*D25 -> 1295458 | G25: Reputed Indian make | I25: 647000 | J25: =I25*D25 -> 647000
B26: Total | F26: =SUM(F5:F25) -> 49066536
J28: =SUM(J4:J27) -> 23398815

Sheet Support 3 Years
A2: SN | B2: Item Description | C2: Specifications | D2: Unit | E2: Qty | F2: Rate per unit (INR) | G2: Total Amount INR | H2: Remarks | J2: Monthly Salary and perdiem/other cost | K2: Total Cost for three years
A3: 1 | B3: Manpower Support for 3 Years (Onsite) | C3: One Onsite L2 Engineer | D3: Lumsum | E3: 1 | F3: 14280000 | G3: =F3*E3 -> 14280000 | H3: One On Site Engineer | J3: =200000+100000 -> 300000 | K3: =J3*36 -> 10800000
A4: 2 | B4: Manpower Support for 3 Years (Offsite) | C4: Two Offsite L2 Engineers for different domains (Cloud, Network & Security) | D4: Lumsum | E4: 1 | F4: 4778470 | G4: =F4*E4 -> 4778470 | H4: Offsite Support through Shared L2 Engineers | J4: 100000 | K4: =J4*36 -> 3600000
C5: TOTAL | G5: =SUM(G3:G4) -> 19058470
K6: =SUM(K3:K4) -> 14400000

Sheet Migration Support 
B2: Migration Assistance Related Activities
B4: SI.No | C4: Activities
B5: Infrastructure setup and provisioning
B6: 1 | C6: Facilitate to setup cloud or on-premises environments (servers, networking, storage)
B7: 2 | C7: Sizing VM Details based on existing infrastructure
B8: Data Migration Assitance - Limited
B9: 3 | C9: Guidance on transferring databases, files or configurations.
B10: 4 | C10: Providing recommendations for data migration tools. However the tools will be arranged by MoFA/Ethiopia
B11: Basic Compatibility Checks
B12: 5 | C12: High-level assessment of whether the application can run in the new environment
B13: 6 | C13: Providing documentation or best practices for the migration
B14: Troubleshooting Assistance - Limited
B15: 7 | C15: Helping identify infrastructure-related issues if the application doesn’t work post-migration
B16: 8 | C16: Logs or error message analysis (without debugging the app itself)
B17: Best-Effort Guidance
B18: 9 | C18: Answering queries related to migration approaches
B19: 10 | C19: Referring to third-party documentation or experts
B22: Activities Not Considered under RailTel's Scope
B23: SI.No | C23: Activities
B24: 1 | C24: No rewriting or refactoring of application code
B25: 2 | C25: No debugging or fixing of application-related issues.
B26: 3 | C26: No OS related support based on application requirement
B27: 4 | C27: No direct migration or installation of the application
B28: 5 | C28: No direct migration or installation of the database

Sheet Implementation Resources
B4: SI.No | C4: Resources | D4: Qty | E4: Months | F4: Total Manmonths | G4: Unit Price | H4: Total Price
B5: 1 | C5: Project Manager | D5: 1 | E5: 8 | F5: =D5*E5 -> 8 | G5: 200000 | H5: =G5*E5 -> 1600000
B6: 2 | C6: NON-IT Consultant | D6: 1 | E6: 2 | F6: =D6*E6 -> 2 | G6: 300000 | H6: =G6*E6 -> 600000
B7: 3 | C7: NON-IT Expert | D7: 1 | E7: 8 | F7: =D7*E7 -> 8 | G7: 150000 | H7: =G7*E7 -> 1200000
B8: 4 | C8: Implementation/Solution Lead | D8: 1 | E8: 3 | F8: =D8*E8 -> 3 | G8: 300000 | H8: =G8*E8 -> 900000
B9: 5 | C9: Network & Security expert | D9: 1 | E9: 4 | F9: =D9*E9 -> 4 | G9: 200000 | H9: =G9*E9 -> 800000
B10: 6 | C10: Compute Expert | D10: 1 | E10: 4 | F10: =D10*E10 -> 4 | G10: 200000 | H10: =G10*E10 -> 800000
B11: 7 | C11: Engineers | D11: 2 | E11: 8 | F11: =D11*E11 -> 16 | G11: 100000 | H11: =G11*E11*D11 -> 1600000
B12: Salary with Insurance | H12: =SUM(H5:H11) -> 7500000
B13: Travel cost (15 Visits) | H13: 1500000
B14: Accomadation , Local Travel, Food Expenses (50 Man Months) | H14: =50*1200*90 -> 5400000
B15: Total cost during implementation | H15: =SUM(H12:H14) -> 14400000

Sheet  Non-IT components Breakup
A1: Non-IT Services for Data Center (Approximate Breakup )
A2: S. No. | B2: Item Descriotion | C2: UOM | D2: Qty
A5: 1 | B5: Civil and Interior works comprising of demolition works, construction of partition walls, Supply and installation of Fire rated doors, installation of vinyl flooring, DG foundation and miscellaneous works | C5: Lot | D5: 1
B6: Demolition works : Existing walls, Roads, Lightings , Window Grills, Doors, Vents, etc. Also include removal and dumping of debris as per local norms. | C6: Ls | D6: 1
B7: Construction of partition walls and Brick work and plastering for closing the Windows | C7: Sft | D7: =(25*4)*10.76 -> 1076
B8: Anti-termite treatment for the wall and floors of the Data Center. | C8: Sft | D8: 3000
B9: Construction of DG foundation for 160 kVA | C9: Ls | D9: 1
B10: Construction of Ramp cum Pathway to the DG Set for providing Trolley movement up to DG Belly/ Skid tank. | C10: Ls | D10: 1
B11: Covering of Drainage pipes inside the proposed server and Electrical Rooms | C11: Ls | D11: 1
B12: Painting of all the partition walls and newly constructed walls | C12: Sft | D12: =D7*2 -> 2152
B13: Closure of windows/Vents available in DC area | C13: Sft | D13: =((16+3)*1.2)*10.76 -> 245.328
B14: Supply and installation of approximate 8 feet height fire rated doors | C14: Nos. | D14: 7
B15: Supply Installation of Anti-static Vinyl flooring | C15: Sft | D15: =1550*1.1 -> 1705
B16: Supply , fixing of Signages for Doors and Rooms. | C16: Ls | D16: 1
B17: Supplying and Fixing of Foundation Plate / Logos | C17: Job | D17: 1
B18: Laying of Hume pipes across road for cabling works | C18: Mtrs | D18: 6
B19: Manholes for the Underground cable paths. | C19: Ls | D19: 1
B20: Restoring the Roads after road cutting for underground cables. | C20: Job | D20: 1
B21: Construction of Platforms for outdoor Units of Air conditioning system. | C21: Nos. | D21: 6
B22: MS framing works for stacking of Outdoor AC units. | C22: Nos. | D22: 6
B23: Restoration of surrounding area tiles after earthing and cabling works. | C23: Job | D23: 1
B24: Cut-out on the partition walls for cable trays and it’s closures after laying the cables and copper pipes. | C24: Job | D24: 1
B25: Arrangements for Environments and Health safety, Personal Protective Equipment as per local norms. | C25: Job | D25: 1
B26: Clearing and cleaning of sites periodically and on completion of civil works which includes dumping of debris as per local norms. | C26: Job | D26: 1
B27: Additional Partition and Doors along with painting between two parts of the Server Hall. | C27: LS | D27: 1
A28: 2 | B28: Supply and installation of furniture (console desk with storage space for PC/workstation and meadium back chairs) for NOC room | C28: Nos. | D28: 3
A29: 3 | B29: Supply and installation of laminated worktable & chair for staging room | C29: No. | D29: 1
A30: 4 | B30: Supply, installation, testing and commissioning of DG Set | C30: No. | D30: 1
B31: Supply of DG from India in packaged with AMF panel | C31: No. | D31: 1
B32: Re-assembling with silencer and exhaust pipes, Installation and commissioning of DG set at Site. | C32: Ls | D32: 1
B33: Warranty support from Local dealers of OEMs | C33: Years | D33: 3
B34: AMC support | C34: Years | D34: 3
B35: Spares for the immediate support and restoration | C35: Ls | D35: 1
B36: Diesel consumption during testing and commissioning. | C36: Ltrs | D36: 200
B37: Documentation and SoP development for Three year O&M | C37: Job | D37: 1
B38: Knowledge transfer regarding operation & Maintenance of DG Set through staff training. | C38: Job | D38: 1
B39: Supply and fixing Signages for DG Area | C39: Nos. | D39: 4
A40: 5 | B40: Supply, installation, testing and commissioning of 60 kVA UPS | C40: Nos. | D40: 2
B41: Supply of 3 phase in-line UPS with ≥0.96PF | C41: Nos. | D41: 2
B42: Supply of VRLA Batteries for 15mins backup with inter connectiving cables between batteries | C42: Sets | D42: 2
...
